Traceback (most recent call last):
  File "C:\Users\sergi\miniconda3\envs\entorno_sc\Lib\site-packages\jupyter_core\utils\__init__.py", line 154, in wrapped
    asyncio.get_running_loop()
RuntimeError: no running event loop

During handling of the above exception, another exception occurred:

Traceback (most recent call last):
  File "C:\Users\sergi\miniconda3\envs\entorno_sc\Lib\site-packages\jupyter_cache\executors\utils.py", line 58, in single_nb_execution
    executenb(
  File "C:\Users\sergi\miniconda3\envs\entorno_sc\Lib\site-packages\nbclient\client.py", line 1319, in execute
    return NotebookClient(nb=nb, resources=resources, km=km, **kwargs).execute()
           ^^^^^^^^^^^^^^^^^^^^^^^^^^^^^^^^^^^^^^^^^^^^^^^^^^^^^^^^^^^^^^^^^^^^^
  File "C:\Users\sergi\miniconda3\envs\entorno_sc\Lib\site-packages\jupyter_core\utils\__init__.py", line 158, in wrapped
    return loop.run_until_complete(inner)
           ^^^^^^^^^^^^^^^^^^^^^^^^^^^^^^
  File "C:\Users\sergi\miniconda3\envs\entorno_sc\Lib\asyncio\base_events.py", line 654, in run_until_complete
    return future.result()
           ^^^^^^^^^^^^^^^
  File "C:\Users\sergi\miniconda3\envs\entorno_sc\Lib\site-packages\nbclient\client.py", line 709, in async_execute
    await self.async_execute_cell(
  File "C:\Users\sergi\miniconda3\envs\entorno_sc\Lib\site-packages\nbclient\client.py", line 1062, in async_execute_cell
    await self._check_raise_for_error(cell, cell_index, exec_reply)
  File "C:\Users\sergi\miniconda3\envs\entorno_sc\Lib\site-packages\nbclient\client.py", line 918, in _check_raise_for_error
    raise CellExecutionError.from_cell_and_msg(cell, exec_reply_content)
nbclient.exceptions.CellExecutionError: An error occurred while executing the following cell:
------------------
# Separar columnas por tipo
num_cols = df.select_dtypes(include=[np.number]).columns.tolist()
cat_cols = [c for c in df.columns if c not in num_cols]

print("NumÃ©ricas:", len(num_cols), "â†’", num_cols[:5], "...")
print("CategÃ³ricas:", len(cat_cols), "â†’", cat_cols[:5], "...")

------------------


[31m---------------------------------------------------------------------------[39m
[31mNameError[39m                                 Traceback (most recent call last)
[36mCell[39m[36m [39m[32mIn[1][39m[32m, line 2[39m
[32m      1[39m [38;5;66;03m# Separar columnas por tipo[39;00m
[32m----> [39m[32m2[39m num_cols = [43mdf[49m.select_dtypes(include=[np.number]).columns.tolist()
[32m      3[39m cat_cols = [c [38;5;28;01mfor[39;00m c [38;5;129;01min[39;00m df.columns [38;5;28;01mif[39;00m c [38;5;129;01mnot[39;00m [38;5;129;01min[39;00m num_cols]
[32m      5[39m [38;5;28mprint[39m([33m"[39m[33mNumÃ©ricas:[39m[33m"[39m, [38;5;28mlen[39m(num_cols), [33m"[39m[33mâ†’[39m[33m"[39m, num_cols[:[32m5[39m], [33m"[39m[33m...[39m[33m"[39m)

[31mNameError[39m: name 'df' is not defined

